Workbook

Sheet calendar
A1: Sat | B1: Sun | C1: Mon | D1: Tue | E1: Wed | F1: Thu | G1: Fri
A2: 45290 | B2: 45291 | C2: 45292 | D2: 45293 | E2: 45294 | F2: 45295 | G2: 45296 | H2: Week-1
A3: =G2+1 -> 45297 | B3: =A3+1 -> 45298 | C3: =B3+1 -> 45299 | D3: =C3+1 -> 45300 | E3: =D3+1 -> 45301 | F3: =E3+1 -> 45302 | G3: =F3+1 -> 45303 | H3: Week-2
A4: =G3+1 -> 45304 | B4: =A4+1 -> 45305 | C4: =B4+1 -> 45306 | D4: =C4+1 -> 45307 | E4: =D4+1 -> 45308 | F4: =E4+1 -> 45309 | G4: =F4+1 -> 45310 | H4: Week-3
A5: =G4+1 -> 45311 | B5: =A5+1 -> 45312 | C5: =B5+1 -> 45313 | D5: =C5+1 -> 45314 | E5: =D5+1 -> 45315 | F5: =E5+1 -> 45316 | G5: =F5+1 -> 45317 | H5: Week-4
A6: =G5+1 -> 45318 | B6: =A6+1 -> 45319 | C6: =B6+1 -> 45320 | D6: =C6+1 -> 45321 | E6: =D6+1 -> 45322 | F6: =E6+1 -> 45323 | G6: =F6+1 -> 45324 | H6: Week-5
A7: =G6+1 -> 45325 | B7: =A7+1 -> 45326 | C7: =B7+1 -> 45327 | D7: =C7+1 -> 45328 | E7: =D7+1 -> 45329 | F7: =E7+1 -> 45330 | G7: =F7+1 -> 45331 | H7: Week-6
A8: =G7+1 -> 45332 | B8: =A8+1 -> 45333 | C8: =B8+1 -> 45334 | D8: =C8+1 -> 45335 | E8: =D8+1 -> 45336 | F8: =E8+1 -> 45337 | G8: =F8+1 -> 45338 | H8: Week-7
A9: =G8+1 -> 45339 | B9: =A9+1 -> 45340 | C9: =B9+1 -> 45341 | D9: =C9+1 -> 45342 | E9: =D9+1 -> 45343 | F9: =E9+1 -> 45344 | G9: =F9+1 -> 45345 | H9: Week-8
A10: =G9+1 -> 45346 | B10: =A10+1 -> 45347 | C10: =B10+1 -> 45348 | D10: =C10+1 -> 45349 | E10: =D10+1 -> 45350 | F10: =E10+1 -> 45351 | G10: =F10+1 -> 45352 | H10: Week-9
A11: =G10+1 -> 45353 | B11: =A11+1 -> 45354 | C11: =B11+1 -> 45355 | D11: =C11+1 -> 45356 | E11: =D11+1 -> 45357 | F11: =E11+1 -> 45358 | G11: =F11+1 -> 45359 | H11: Week-10
A12: =G11+1 -> 45360 | B12: =A12+1 -> 45361 | C12: =B12+1 -> 45362 | D12: =C12+1 -> 45363 | E12: =D12+1 -> 45364 | F12: =E12+1 -> 45365 | G12: =F12+1 -> 45366 | H12: Week-11
A13: =G12+1 -> 45367 | B13: =A13+1 -> 45368 | C13: =B13+1 -> 45369 | D13: =C13+1 -> 45370 | E13: =D13+1 -> 45371 | F13: =E13+1 -> 45372 | G13: =F13+1 -> 45373 | H13: Week-12
A14: =G13+1 -> 45374 | B14: =A14+1 -> 45375 | C14: =B14+1 -> 45376 | D14: =C14+1 -> 45377 | E14: =D14+1 -> 45378 | F14: =E14+1 -> 45379 | G14: =F14+1 -> 45380 | H14: Week-13
... A70: =G69+1 -> 45766 | B70: =A70+1 -> 45767 | C70: =B70+1 -> 45768 | D70: =C70+1 -> 45769 | E70: =D70+1 -> 45770 | F70: =E70+1 -> 45771 | G70: =F70+1 -> 45772 | H70: Week-69

Sheet Data
F1: =VLOOKUP(F3,calendar!$A$2:$H$70,8) -> Week-1 | G1: =VLOOKUP(G3,calendar!$A$2:$H$70,8) -> Week-1 | H1: =VLOOKUP(H3,calendar!$A$2:$H$70,8) -> Week-1 | I1: =VLOOKUP(I3,calendar!$A$2:$H$70,8) -> Week-1 | J1: =VLOOKUP(J3,calendar!$A$2:$H$70,8) -> Week-1 | K1: =VLOOKUP(K3,calendar!$A$2:$H$70,8) -> Week-2 | L1: =VLOOKUP(L3,calendar!$A$2:$H$70,8) -> Week-2 | M1: =VLOOKUP(M3,calendar!$A$2:$H$70,8) -> Week-2 | ... Y1: =VLOOKUP(Y3,calendar!$A$2:$H$70,8) -> Week-4 | AA1: =VLOOKUP(AA3,calendar!$A$2:$H$70,8) -> Week-4 | AB1: =VLOOKUP(AB3,calendar!$A$2:$H$70,8) -> Week-4 | AC1: =VLOOKUP(AC3,calendar!$A$2:$H$70,8) -> Week-4 | AD1: =VLOOKUP(AD3,calendar!$A$2:$H$70,8) -> Week-4 | AE1: =VLOOKUP(AE3,calendar!$A$2:$H$70,8) -> Week-4 | AF1: =VLOOKUP(AF3,calendar!$A$2:$H$70,8) -> Week-5 | AG1: =VLOOKUP(AG3,calendar!$A$2:$H$70,8) -> Week-5 | AH1: =VLOOKUP(AH3,calendar!$A$2:$H$70,8) -> Week-5 | ... MQ1: =VLOOKUP(MQ3,calendar!$A$2:$H$70,8) -> Week-51 | MR1: =VLOOKUP(MR3,calendar!$A$2:$H$70,8,FALSE) -> #N/A | MS1: =VLOOKUP(MS3,calendar!$A$2:$H$70,8) -> Week-51 | MT1: =VLOOKUP(MT3,calendar!$A$2:$H$70,8) -> Week-51 | MU1: =VLOOKUP(MU3,calendar!$A$2:$H$70,8) -> Week-51 | MV1: =VLOOKUP(MV3,calendar!$A$2:$H$70,8) -> Week-51 | MW1: =VLOOKUP(MW3,calendar!$A$2:$H$70,8) -> Week-52 | MX1: =VLOOKUP(MX3,calendar!$A$2:$H$70,8) -> Week-52 | MY1: =VLOOKUP(MY3,calendar!$A$2:$H$70,8) -> Week-52 | MZ1: =VLOOKUP(MZ3,calendar!$A$2:$H$70,8) -> Week-52 | ... NF1: =VLOOKUP(NF3,calendar!$A$2:$H$70,8) -> Week-53 | NG1: week-53
D2: Last Rec | F2: =F3 -> 45292 | G2: =G3 -> 45293 | H2: =H3 -> 45294 | I2: =I3 -> 45295 | J2: =J3 -> 45296 | K2: =K3 -> 45297 | L2: =L3 -> 45298 | M2: =M3 -> 45299 | ... NG2: =NG3 -> 31-12
C3: Avg | D3: =LOOKUP(2,1/(F3:XA3<>""),F3:XA3) -> 31-12 | F3: 45292 | G3: 45293 | H3: 45294 | I3: 45295 | J3: 45296 | K3: 45297 | L3: 45298 | M3: 45299 | N3: 45300 | O3: 45301 | P3: 45302 | Q3: 45303 | R3: 45304 | S3: 45305 | T3: 45306 | U3: 45307 | V3: 45308 | W3: 45309 | X3: 45310 | Y3: 45311 | Z3: 45312 | AA3: 45313 | AB3: 45314 | AC3: 45315 | AD3: 45316 | AE3: 45317 | AF3: 45318 | AG3: 45319 | AH3: 45320 | AI3: 45321 | AJ3: 45322 | AK3: 45323 | AL3: 45324 | AM3: 45325 | AN3: 45326 | AO3: 45327 | AP3: 45328 | AQ3: 45329 | AR3: 45330 | AS3: 45331 | AT3: 45332 | AU3: 45333 | AV3: 45334 | AW3: 45335 | AX3: 45336 | AY3: 45337 | AZ3: 45338 | BA3: 45339 | BB3: 45340 | BC3: 45341 | BD3: 45342 | BE3: 45343 | BF3: 45344 | BG3: 45345 | BH3: 45346 | BI3: 45347 | BJ3: 45348 | BK3: 45349 | BL3: 45350 | BM3: 45351 | BN3: 45352 | BO3: 45353 | BP3: 45354 | BQ3: 45355 | BR3: 45356 | BS3: 45357 | BT3: 45358 | BU3: 45359 | BV3: 45360 | BW3: 45361 | BX3: 45362 | BY3: 45363 | BZ3: 45364 | CA3: 45365 | CB3: 45366 | CC3: 45367 | CD3: 45368 | CE3: 45369 | CF3: 45370 | CG3: 45371 | CH3: 45372 | CI3: 45373 | CJ3: 45374 | CK3: 45375 | CL3: 45376 | CM3: 45377 | CN3: 45378 | CO3: 45379 | CP3: 45380 | CQ3: 45381 | CR3: 45382 | CS3: 45383 | CT3: 45384 | CU3: 45385 | CV3: 45386 | CW3: 45387 | CX3: 45388 | CY3: 45389 | CZ3: 45390 | DA3: 45391 | DB3: 45392 | DC3: 45393 | DD3: 45394 | DE3: 45395 | DF3: 45396 | DG3: 45397 | DH3: 45398 | DI3: 45399 | DJ3: 45400 | DK3: 45401 | DL3: 45402 | DM3: 45403 | DN3: 45404 | DO3: 45405 | DP3: 45406 | DQ3: 45407 | DR3: 45408 | DS3: 45409 | DT3: 45410 | DU3: 45411 | DV3: 45412 | DW3: 45413 | DX3: 45414 | DY3: 45415 | DZ3: 45416 | EA3: 45417 | EB3: 45418 | EC3: 45419 | ED3: 45420 | EE3: 45421 | EF3: 45422 | EG3: 45423 | EH3: 45424 | EI3: 45425 | EJ3: 45426 | EK3: 45427 | EL3: 45428 | EM3: 45429 | EN3: 45430 | EO3: 45431 | EP3: 45432 | EQ3: 45433 | ER3: 45434 | ES3: 45435 | ET3: 45436 | EU3: 45437 | EV3: 45438 | EW3: 45439 | EX3: 45440 | EY3: 45441 | EZ3: 45442 | FA3: 45443 | FB3: 45444 | FC3: 45445 | FD3: 45446 | FE3: 45447 | FF3: 45448 | FG3: 45449 | FH3: 45450 | FI3: 45451 | FJ3: 45452 | FK3: 45453 | FL3: 45454 | FM3: 45455 | FN3: 45456 | FO3: 45457 | FP3: 45458 | FQ3: 45459 | FR3: 45460 | FS3: 45461 | FT3: 45462 | FU3: 45463 | FV3: 45464 | FW3: 45465 | FX3: 45466 | FY3: 45467 | FZ3: 45468 | GA3: 45469 | GB3: 45470 | GC3: 45471 | GD3: 45472 | GE3: 45473 | GF3: 45474 | GG3: 45475 | GH3: 45476 | GI3: 45477 | GJ3: 45478 | GK3: 45479 | GL3: 45480 | GM3: 45481 | GN3: 45482 | GO3: 45483 | GP3: 45484 | GQ3: 45485 | GR3: 45486 | GS3: 45487 | GT3: 45488 | GU3: 45489 | GV3: 45490 | GW3: 45491 | GX3: 45492 | GY3: 45493 | GZ3: 45494 | HA3: 45495 | HB3: 45496 | HC3: 45497 | HD3: 45498 | HE3: 45499 | HF3: 45500 | HG3: 45501 | HH3: 45502 | HI3: 45503 | HJ3: 45504 | HK3: 45505 | HL3: 45506 | HM3: 45507 | HN3: 45508 | HO3: 45509 | HP3: 45510 | HQ3: 45511 | HR3: 45512 | HS3: 45513 | HT3: 45514 | HU3: 45515 | HV3: 45516 | HW3: 45517 | HX3: 45518 | HY3: 45519 | HZ3: 45520 | IA3: 45521 | IB3: 45522 | IC3: 45523 | ID3: 45524 | IE3: 45525 | IF3: 45526 | IG3: 45527 | IH3: 45528 | II3: 45529 | IJ3: 45530 | IK3: 45531 | IL3: 45532 | IM3: 45533 | IN3: 45534 | IO3: 45535 | IP3: 45536 | IQ3: 45537 | IR3: 45538 | IS3: 45539 | IT3: 45540 | IU3: 45541 | IV3: 45542 | IW3: 45543 | IX3: 45544 | IY3: 45545 | IZ3: 45546 | JA3: 45547 | JB3: 45548 | JC3: 45549 | JD3: 45550 | JE3: 45551 | JF3: 45552 | JG3: 45553 | JH3: 45554 | JI3: 45555 | JJ3: 45556 | JK3: 45557 | JL3: 45558 | JM3: 45559 | JN3: 45560 | JO3: 45561 | JP3: 45562 | JQ3: 45563 | JR3: 45564 | JS3: 45565 | JT3: 45566 | JU3: 45567 | JV3: 45568 | JW3: 45569 | JX3: 45570 | JY3: 45571 | JZ3: 45572 | KA3: 45573 | KB3: 45574 | KC3: 45575 | KD3: 45576 | KE3: 45577 | KF3: 45578 | KG3: 45579 | KH3: 45580 | KI3: 45581 | KJ3: 45582 | KK3: 45583 | KL3: 45584 | KM3: 45585 | KN3: 45586 | KO3: 45587 | KP3: 45588 | KQ3: 45589 | KR3: 45590 | KS3: 45591 | KT3: 45592 | KU3: 45593 | KV3: 45594 | KW3: 45595 | KX3: 45596 | KY3: 45597 | KZ3: 45598 | LA3: 45599 | LB3: 45600 | LC3: 45601 | LD3: 45602 | LE3: 45603 | LF3: 45604 | LG3: 45605 | LH3: 45606 | LI3: 45607 | LJ3: 45608 | LK3: 45609 | LL3: 45610 | LM3: 45611 | LN3: 45612 | LO3: 45613 | LP3: 45614 | LQ3: 45615 | LR3: 45616 | LS3: 45617 | LT3: 45618 | LU3: 45619 | LV3: 45620 | LW3: 45621 | LX3: 45622 | LY3: 45623 | LZ3: 45624 | MA3: 45625 | MB3: 45626 | MC3: 45627 | MD3: 45628 | ME3: 45629 | MF3: 45630 | MG3: 45631 | MH3: 45632 | MI3: 45633 | MJ3: 45634 | MK3: 45635 | ML3: 45636 | MM3: 45637 | MN3: 45638 | MO3: 45639 | MP3: 45640 | MQ3: 45641 | MR3: 45642 | MS3: 45643 | MT3: 45644 | MU3: 45645 | MV3: 45646 | MW3: 45647 | MX3: 45648 | MY3: 45649 | MZ3: 45650 | NA3: 45651 | NB3: 45652 | NC3: 45653 | ND3: 45654 | NE3: 45655 | NF3: 45656 | NG3: 31-12
B4: Total Incoming Calls to 150 | C4: =INT(AVERAGE(F4:LI4)) -> 16576 | D4: =LOOKUP(2,1/(F4:XA4<>""),F4:XA4) -> 17229 | F4: 10899 | G4: 11487 | H4: 11232 | I4: 12015 | J4: 10982 | K4: 14207 | L4: 12396 | M4: 12190 | N4: 13606 | O4: 12844 | P4: 12486 | Q4: 11406 | R4: 12811 | S4: 13564 | T4: 12851 | U4: 13644 | V4: 13164 | W4: 13781 | X4: 12620 | Y4: 12216 | Z4: 12259 | AA4: 11027 | AB4: 10996 | AC4: 11045 | AD4: 12353 | AE4: 11138 | AF4: 12118 | AG4: 11380 | AH4: 10543 | AI4: 10440 | AJ4: 31376 | AK4: 14634 | AL4: 12025 | AM4: 13621 | AN4: 13739 | AO4: 14939 | AP4: 15015 | AQ4: 14622 | AR4: 15365 | AS4: 12639 | AT4: 16057 | AU4: 14240 | AV4: 15384 | AW4: 14091 | AX4: 14611 | AY4: 17269 | AZ4: 13563 | BA4: 15523 | BB4: 14678 | BC4: 13815 | BD4: 13859 | BE4: 14200 | BF4: 13720 | BG4: 11649 | BH4: 32899 | BI4: 22974 | BJ4: 16224 | BK4: 15119 | BL4: 14790 | BM4: 20104 | BN4: 12736 | BO4: 12741 | BP4: 13710 | BQ4: 11973 | BR4: 14320 | BS4: 12139 | BT4: 12538 | BU4: 11138 | BV4: 12614 | BW4: 28509 | BX4: 19310 | BY4: 23766 | BZ4: 14207 | CA4: 12698 | CB4: 14867 | CC4: 13728 | CD4: 12630 | CE4: 12903 | CF4: 12815 | CG4: 14382 | CH4: 12830 | CI4: 12162 | CJ4: 13258 | CK4: 12914 | CL4: 4966 | CM4: 9750 | CN4: 14066 | CO4: 14175 | CP4: 12805 | CQ4: 15199 | CR4: 13610 | CS4: 15602 | CT4: 14242 | CU4: 14908 | CV4: 15227 | CW4: 14028 | CX4: 13660 | CY4: 14359 | CZ4: 13546 | DA4: 13651 | DB4: 13250 | DC4: 12901 | DD4: 14809 | DE4: 15714 | DF4: 15701 | DG4: 16858 | DH4: 15939 | DI4: 14820 | DJ4: 14808 | DK4: 12767 | DL4: 14116 | DM4: 13465 | DN4: 14854 | DO4: 14221 | DP4: 14320 | DQ4: 32843 | DR4: 17219 | DS4: 18308 | DT4: 17778 | DU4: 16956 | DV4: 16449 | DW4: 15536 | DX4: 18514 | DY4: 11841 | DZ4: 14296 | EA4: 15095 | EB4: 15536 | EC4: 18395 | ED4: 15406 | EE4: 17712 | EF4: 18831 | EG4: 17314 | EH4: 16658 | EI4: 16060 | EJ4: 17986 | EK4: 20733 | EL4: 16484 | EM4: 15805 | EN4: 24862 | EO4: 18636 | EP4: 16933 | EQ4: 27296 | ER4: 20842 | ES4: 33278 | ET4: 22886 | EU4: 17842 | EV4: 16572 | EW4: 25996 | EX4: 17671 | EY4: 17208 | EZ4: 21369 | FA4: 15460 | FB4: 17910 | FC4: 19014 | FD4: 16973 | FE4: 19067 | FF4: 18209 | FG4: 17982 | FH4: 13942 | FI4: 16351 | FJ4: 26634 | FK4: 27556 | FL4: 20461 | FM4: 18480 | FN4: 18691 | FO4: 16329 | FP4: 28812 | FQ4: 13500 | FR4: 21422 | FS4: 16009 | FT4: 15857 | FU4: 15966 | FV4: 14114 | FW4: 17428 | FX4: 16204 | FY4: 17388 | FZ4: 17350 | GA4: 16319 | GB4: 15756 | GC4: 13208 | GD4: 15920 | GE4: 18622 | GF4: 20362 | GG4: 18912 | GH4: 17817 | GI4: 19471 | GJ4: 17495 | GK4: 20325 | GL4: 18822 | GM4: 19905 | GN4: 18778 | GO4: 19409 | GP4: 24043 | GQ4: 17550 | GR4: 27138 | GS4: 22318 | GT4: 20483 | GU4: 22317 | GV4: 20563 | GW4: 18833 | GX4: 17960 | GY4: 24975 | GZ4: 20959 | HA4: 18905 | HB4: 19312 | HC4: 18080 | HD4: 17649 | HE4: 13577 | HF4: 18569 | HG4: 28779 | HH4: 22139 | HI4: 19173 | HJ4: 17698 | HK4: 18087 | HL4: 14347 | HM4: 1870 | HN4: 14966 | HO4: 15382 | HP4: 16644 | HQ4: 16796 | HR4: 16548 | HS4: 13742 | HT4: 16489 | HU4: 17199 | HV4: 17514 | HW4: 1772 | HX4: 16609 | HY4: 16712 | HZ4: 12896 | IA4: 12896 | IB4: 25754 | IC4: 22310 | ID4: 17388 | IE4: 16121 | IF4: 16893 | IG4: 14208 | IH4: 15333 | II4: 15235 | IJ4: 14699 | IK4: 15723 | IL4: 17587 | IM4: 15927 | IN4: 12318 | IO4: 14896 | IP4: 17783 | IQ4: 15861 | IR4: 16230 | IS4: 17866 | IT4: 18780 | IU4: 24524 | IV4: 21799 | IW4: 21799 | IX4: 19148 | IY4: 18116 | IZ4: 17856 | JA4: 18231 | JB4: 14183 | JC4: 14463 | JD4: 14440 | JE4: 14715 | JF4: 15474 | JG4: 15620 | JH4: 16959 | JI4: 17282 | JJ4: 16959 | JK4: 15213 | JL4: 13862 | JM4: 15524 | JN4: 13552 | JO4: 15140 | JP4: 13686 | JQ4: 15043 | JR4: 12748 | JS4: 17138 | JT4: 13819 | JU4: 13057 | JV4: 14815 | JW4: 13401 | JX4: 14949 | JY4: 13766 | JZ4: 19960 | KA4: 24477 | KB4: 17051 | KC4: 17177 | KD4: 15922 | KE4: 14957 | KF4: 14998 | KG4: 15069 | KH4: 13688 | KI4: 17776 | KJ4: 20282 | KK4: 29170 | KL4: 25321 | KM4: 27442 | KN4: 44761 | KO4: 26561 | KP4: 27557 | KQ4: 21117 | KR4: 17345 | KS4: 17905 | KT4: 16508 | KU4: 15876 | KV4: 14750 | KW4: 14678 | KX4: 15381 | KY4: 15385 | LG4: 25465 | LH4: 27545 | LI4: 3236 | LJ4: 20721 | LK4: 21673 | LL4: 23645 | LM4: 24747 | LN4: 23269 | LO4: 22028 | LP4: 20300 | LQ4: 24856 | LR4: 24848 | LS4: 29856 | LT4: 26256 | LU4: 32917 | LV4: 32021 | LW4: 28015 | LX4: 26053 | LY4: 24922 | LZ4: 32636 | MA4: 25615 | MB4: 25322 | MC4: 20465 | MD4: 18773 | ME4: 18168 | MF4: 18737 | MG4: 21361 | MH4: 26115 | MI4: 28002 | MJ4: 20317 | MK4: 19062 | ML4: 18413 | MM4: 19171 | MN4: 17678 | MO4: 17673 | MP4: 17671 | MQ4: 16671 | MR4: 17782 | MS4: 16316 | MT4: 15901 | MU4: 16385 | MV4: 14634 | MW4: 15586 | MX4: 61825 | MY4: 62196 | MZ4: 22975 | NA4: 19053 | NB4: 21710 | NC4: 20936 | ND4: 19731 | NE4: 18027 | NF4: 17732 | NG4: 17229
B5: Calls Presented | C5: =INT(AVERAGE(F5:LI5)) -> 11649 | D5: =LOOKUP(2,1/(F5:XA5<>""),F5:XA5) -> 13334 | F5: 8517 | G5: 8681 | H5: 8636 | I5: 9310 | J5: 8329 | K5: 10845 | L5: 9740 | M5: 9533 | N5: 10079 | O5: 10193 | P5: 9535 | Q5: 8954 | R5: 9993 | S5: 10739 | T5: 9931 | U5: 10572 | V5: 10585 | W5: 10085 | X5: 9139 | Y5: 9631 | Z5: 9281 | AA5: 8507 | AB5: 8624 | AC5: 8700 | AD5: 9789 | AE5: 8659 | AF5: 9451 | AG5: 8930 | AH5: 8147 | AI5: 8057 | AJ5: 10406 | AK5: 10845 | AL5: 9239 | AM5: 10654 | AN5: 10690 | AO5: 11769 | AP5: 11664 | AQ5: 11527 | AR5: 11801 | AS5: 9526 | AT5: 11398 | AU5: 10988 | AV5: 11244 | AW5: 106554 | AX5: 11107 | AY5: 11383 | AZ5: 10037 | BA5: 11886 | BB5: 11765 | BC5: 10937 | BD5: 10905 | BE5: 10977 | BF5: 10668 | BG5: 9062 | BH5: 11390 | BI5: 13436 | BJ5: 12051 | BK5: 11412 | BL5: 11244 | BM5: 11825 | BN5: 9614 | BO5: 9913 | BP5: 10881 | BQ5: 9285 | BR5: 10842 | BS5: 9211 | BT5: 9792 | BU5: 8494 | BV5: 9850 | BW5: 10043 | BX5: 12048 | BY5: 9103 | BZ5: 10166 | CA5: 9710 | CB5: 9820 | CC5: 10059 | CD5: 9571 | CE5: 9531 | CF5: 9735 | CG5: 10023 | CH5: 9762 | CI5: 9272 | CJ5: 9810 | CK5: 9588 | CL5: 4060 | CM5: 6544 | CN5: 10478 | CO5: 10369 | CP5: 9754 | CQ5: 10872 | CR5: 10334 | CS5: 10449 | CT5: 10348 | CU5: 10547 | CV5: 10927 | CW5: 10496 | CX5: 10142 | CY5: 10694 | CZ5: 10464 | DA5: 10412 | DB5: 10321 | DC5: 7912 | DD5: 10422 | DE5: 12019 | DF5: 11841 | DG5: 12340 | DH5: 12045 | DI5: 11513 | DJ5: 11575 | DK5: 9731 | DL5: 11103 | DM5: 10519 | DN5: 11089 | DO5: 11076 | DP5: 11195 | DQ5: 14476 | DR5: 11930 | DS5: 13206 | DT5: 12936 | DU5: 12556 | DV5: 12617 | DW5: 12639 | DX5: 11349 | DY5: 9145 | DZ5: 11093 | EA5: 11598 | EB5: 11719 | EC5: 12723 | ED5: 11550 | EE5: 12609 | EF5: 12991 | EG5: 12395 | EH5: 12710 | EI5: 12180 | EJ5: 12683 | EK5: 13013 | EL5: 12435 | EM5: 10661 | EN5: 12644 | EO5: 12390 | EP5: 12748 | EQ5: 11893 | ER5: 12354 | ES5: 15443 | ET5: 12977 | EU5: 12118 | EV5: 12057 | EW5: 15032 | EX5: 12547 | EY5: 1112 | EZ5: 12838 | FA5: 10506 | FB5: 12359 | FC5: 13365 | FD5: 12495 | FE5: 12765 | FF5: 12786 | FG5: 12518 | FH5: 10367 | FI5: 12055 | FJ5: 13479 | FK5: 16259 | FL5: 13991 | FM5: 12889 | FN5: 13381 | FO5: 11132 | FP5: 15171 | FQ5: 9290 | FR5: 10478 | FS5: 12057 | FT5: 11832 | FU5: 11919 | FV5: 10103 | FW5: 12047 | FX5: 12468 | FY5: 12682 | FZ5: 12462 | GA5: 12262 | GB5: 12058 | GC5: 9839 | GD5: 11862 | GE5: 12724 | GF5: 12887 | GG5: 12919 | GH5: 12501 | GI5: 13259 | GJ5: 11389 | GK5: 13644 | GL5: 13327 | GM5: 13201 | GN5: 13250 | GO5: 13408 | GP5: 14563 | GQ5: 12010 | GR5: 14919 | GS5: 14876 | GT5: 13954 | GU5: 14057 | GV5: 13502 | GW5: 12967 | GX5: 11866 | GY5: 14475 | GZ5: 14390 | HA5: 13173 | HB5: 13644 | HC5: 13148 | HD5: 12746 | HE5: 10124 | HF5: 11947 | HG5: 14628 | HH5: 13487 | HI5: 12892 | HJ5: 12553 | HK5: 12613 | HL5: 10057 | HM5: 12497 | HN5: 11347 | HO5: 11427 | HP5: 12435 | HQ5: 12145 | HR5: 1259 | HS5: 10121 | HT5: 12213 | HU5: 12603 | HV5: 12753 | HW5: 12910 | HX5: 12266 | HY5: 12124 | HZ5: 9724 | IA5: 13457 | IB5: 14182 | IC5: 12642 | ID5: 12389 | IE5: 11999 | IF5: 11386 | IG5: 10273 | IH5: 11219 | II5: 11157 | IJ5: 10577 | IK5: 11524 | IL5: 12413 | IM5: 11710 | IN5: 9257 | IO5: 10778 | IP5: 12033 | IQ5: 11397 | IR5: 11646 | IS5: 12298 | IT5: 12974 | IU5: 11353 | IV5: 13867 | IW5: 13861 | IX5: 13109 | IY5: 12570 | IZ5: 12290 | JA5: 12475 | JB5: 9827 | JC5: 10280 | JD5: 10069 | JE5: 9931 | JF5: 10331 | JG5: 10790 | JH5: 11945 | JI5: 10973 | JJ5: 11934 | JK5: 10548 | JL5: 10000 | JM5: 10825 | JN5: 9509 | JO5: 10432 | JP5: 9458 | JQ5: 10813 | JR5: 8937 | JS5: 10149 | JT5: 9923 | JU5: 9434 | JV5: 10264 | JW5: 9510 | JX5: 10715 | JY5: 9511 | JZ5: 8178 | KA5: 10364 | KB5: 10939 | KC5: 11390 | KD5: 10199 | KE5: 11001 | KF5: 9975 | KG5: 9632 | KH5: 10350 | KI5: 9225 | KJ5: 11401 | KK5: 13110 | KL5: 15799 | KM5: 16621 | KN5: 17112 | KO5: 16026 | KP5: 14685 | KQ5: 13336 | KR5: 10854 | KS5: 11638 | KT5: 10387 | KU5: 10001 | KV5: 9585 | KW5: 9239 | KX5: 9800 | KY5: 9361 | LG5: 17973 | LH5: 20744 | LI5: 17443 | LJ5: 15161 | LK5: 16116 | LL5: 18072 | LM5: 17096 | LN5: 17593 | LO5: 16688 | LP5: 15186 | LQ5: 19432 | LR5: 19089 | LS5: 22930 | LT5: 18556 | LU5: 26302 | LV5: 25553 | LW5: 22121 | LX5: 20170 | LY5: 19586 | LZ5: 26101 | MA5: 18233 | MB5: 19872 | MC5: 15624 | MD5: 14242 | ME5: 13843 | MF5: 14591 | MG5: 17086 | MH5: 19104 | MI5: 22673 | MJ5: 15955 | MK5: 15118 | ML5: 14047 | MM5: 15578 | MN5: 14799 | MO5: 11560 | MP5: 13703 | MQ5: 12774 | MR5: 13745 | MS5: 12511 | MT5: 12247 | MU5: 12491 | MV5: 10223 | MW5: 11483 | MX5: 53905 | MY5: 54563 | MZ5: 17832 | NA5: 14508 | NB5: 16985 | NC5: 15410 | ND5: 15291 | NE5: 13819 | NF5: 13547 | NG5: 13334
B6: Calls Handled | C6: =INT(AVERAGE(F6:LI6)) -> 8399 | D6: =LOOKUP(2,1/(F6:XA6<>""),F6:XA6) -> 6384 | F6: 7952 | G6: 8273 | H6: 8110 | I6: 8855 | J6: 6910 | K6: 9039 | L6: 9174 | M6: 8803 | N6: 9212 | O6: 9504 | P6: 8955 | Q6: 7210 | R6: 9241 | S6: 9744 | T6: 9203 | U6: 9721 | V6: 9499 | W6: 9440 | X6: 6768 | Y6: 9105 | Z6: 8464 | AA6: 7762 | AB6: 8054 | AC6: 8289 | AD6: 9010 | AE6: 6723 | AF6: 8582 | AG6: 8068 | AH6: 7749 | AI6: 7692 | AJ6: 8761 | AK6: 9472 | AL6: 6892 | AM6: 9220 | AN6: 9552 | AO6: 10736 | AP6: 10693 | AQ6: 10613 | AR6: 10439 | AS6: 6956 | AT6: 7554 | AU6: 9301 | AV6: 9170 | AW6: 9143 | AX6: 9523 | AY6: 9196 | AZ6: 7338 | BA6: 10537 | BB6: 10791 | BC6: 10076 | BD6: 10361 | BE6: 9623 | BF6: 9808 | BG6: 6960 | BH6: 9928 | BI6: 9944 | BJ6: 10181 | BK6: 9733 | BL6: 10318 | BM6: 8778 | BN6: 6279 | BO6: 8860 | BP6: 9779 | BQ6: 8585 | BR6: 9852 | BS6: 8125 | BT6: 8821 | BU6: 5958 | BV6: 8288 | BW6: 1113 | BX6: 8913 | BY6: 5503 | BZ6: 6078 | CA6: 6127 | CB6: 4879 | CC6: 6426 | CD6: 6255 | CE6: 6067 | CF6: 6534 | CG6: 6650 | CH6: 6543 | CI6: 5168 | CJ6: 6205 | CK6: 6311 | CL6: 3133 | CM6: 3972 | CN6: 6781 | CO6: 6849 | CP6: 5406 | CQ6: 6768 | CR6: 6875 | CS6: 6472 | CT6: 6674 | CU6: 6773 | CV6: 6807 | CW6: 5514 | CX6: 6139 | CY6: 6821 | CZ6: 6493 | DA6: 5644 | DB6: 579 | DC6: 5338 | DD6: 5624 | DE6: 8940 | DF6: 9551 | DG6: 9492 | DH6: 9978 | DI6: 9667 | DJ6: 9665 | DK6: 7029 | DL6: 9186 | DM6: 9252 | DN6: 9171 | DO6: 9835 | DP6: 9600 | DQ6: 9904 | DR6: 739 | DS6: 10606 | DT6: 10475 | DU6: 10226 | DV6: 10550 | DW6: 10172 | DX6: 8814 | DY6: 6871 | DZ6: 9380 | EA6: 9930 | EB6: 9345 | EC6: 8680 | ED6: 9169 | EE6: 9518 | EF6: 7266 | EG6: 9075 | EH6: 7960 | EI6: 9587 | EJ6: 9222 | EK6: 9680 | EL6: 9686 | EM6: 5848 | EN6: 9152 | EO6: 9021 | EP6: 9789 | EQ6: 9031 | ER6: 9558 | ES6: 10750 | ET6: 6430 | EU6: 9130 | EV6: 9607 | EW6: 11168 | EX6: 9946 | EY6: 9496 | EZ6: 7826 | FA6: 4436 | FB6: 8237 | FC6: 9336 | FD6: 9833 | FE6: 8578 | FF6: 8670 | FG6: 8755 | FH6: 5319 | FI6: 8819 | FJ6: 9761 | FK6: 10786 | FL6: 9803 | FM6: 9082 | FN6: 9180 | FO6: 6257 | FP6: 9487 | FQ6: 14 | FR6: 0 | FS6: 7864 | FT6: 8598 | FU6: 8469 | FV6: 5891 | FW6: 8340 | FX6: 9188 | FY6: 8912 | FZ6: 8508 | GA6: 8780 | GB6: 8834 | GC6: 6265 | GD6: 8589 | GE6: 9040 | GF6: 8883 | GG6: 8920 | GH6: 9115 | GI6: 9122 | GJ6: 5788 | GK6: 8943 | GL6: 9715 | GM6: 9881 | GN6: 9721 | GO6: 9287 | GP6: 9497 | GQ6: 6885 | GR6: 10180 | GS6: 10906 | GT6: 10243 | GU6: 9540 | GV6: 9889 | GW6: 9634 | GX6: 6387 | GY6: 8935 | GZ6: 10311 | HA6: 9824 | HB6: 9619 | HC6: 9631 | HD6: 9864 | HE6: 6388 | HF6: 9438 | HG6: 10849 | HH6: 10110 | HI6: 9605 | HJ6: 8892 | HK6: 9035 | HL6: 6078 | HM6: 8649 | HN6: 8644 | HO6: 8549 | HP6: 9499 | HQ6: 9304 | HR6: 9524 | HS6: 6023 | HT6: 9262 | HU6: 9245 | HV6: 9538 | HW6: 9345 | HX6: 8840 | HY6: 8752 | HZ6: 6242 | IA6: 8939 | IB6: 8670 | IC6: 9469 | ID6: 9135 | IE6: 8836 | IF6: 7922 | IG6: 6207 | IH6: 8682 | II6: 8551 | IJ6: 8369 | IK6: 8870 | IL6: 8640 | IM6: 9110 | IN6: 6795 | IO6: 8230 | IP6: 8531 | IQ6: 8533 | IR6: 8724 | IS6: 8296 | IT6: 8936 | IU6: 5929 | IV6: 9627 | IW6: 9611 | IX6: 9428 | IY6: 9098 | IZ6: 9389 | JA6: 9467 | JB6: 6415 | JC6: 8405 | JD6: 8097 | JE6: 8035 | JF6: 8490 | JG6: 8600 | JH6: 9694 | JI6: 6809 | JJ6: 8696 | JK6: 8668 | JL6: 8453 | JM6: 8576 | JN6: 8119 | JO6: 8241 | JP6: 5392 | JQ6: 7999 | JR6: 7676 | JS6: 7807 | JT6: 8458 | JU6: 8220 | JV6: 8400 | JW6: 5727 | JX6: 8650 | JY6: 8181 | JZ6: 7302 | KA6: 8829 | KB6: 9062 | KC6: 9609 | KD6: 6927 | KE6: 9571 | KF6: 8844 | KG6: 8281 | KH6: 9016 | KI6: 8557 | KJ6: 9100 | KK6: 7773 | KL6: 12573 | KM6: 13520 | KN6: 13190 | KO6: 12834 | KP6: 11476 | KQ6: 10721 | KR6: 7273 | KS6: 10172 | KT6: 9026 | KU6: 8668 | KV6: 8705 | KW6: 8425 | KX6: 8445 | KY6: 5865 | LG6: 3518 | LH6: 6842 | LI6: 7776 | LJ6: 8334 | LK6: 7505 | LL6: 7464 | LM6: 4925 | LN6: 9242 | LO6: 8348 | LP6: 8753 | LQ6: 6510 | LR6: 7044 | LS6: 7896 | LT6: 4872 | LU6: 6882 | LV6: 6651 | LW6: 6929 | LX6: 6829 | LY6: 6940 | LZ6: 6831 | MA6: 4349 | MB6: 8219 | MC6: 7147 | MD6: 7226 | ME6: 7576 | MF6: 6982 | MG6: 5939 | MH6: 3913 | MI6: 7001 | MJ6: 7645 | MK6: 7486 | ML6: 8086 | MM6: 7551 | MN6: 7906 | MO6: 4553 | MP6: 6784 | MQ6: 7452 | MR6: 6907 | MS6: 7718 | MT6: 7433 | MU6: 7490 | MV6: 4737 | MW6: 7853 | MX6: 8178 | MY6: 8157 | MZ6: 6471 | NA6: 7375 | NB6: 5913 | NC6: 3799 | ND6: 6121 | NE6: 7385 | NF6: 6417 | NG6: 6384
B7: Calls Abandoned | C7: =INT(AVERAGE(F7:LI7)) -> 2986 | D7: =LOOKUP(2,1/(F7:XA7<>""),F7:XA7) -> 6950 | F7: 563 | G7: 403 | H7: 524 | I7: 451 | J7: 1417 | K7: 1805 | L7: 566 | M7: 730 | N7: 866 | O7: 687 | P7: 580 | Q7: 1741 | R7: 747 | S7: 993 | T7: 725 | U7: 848 | V7: 1084 | W7: 645 | X7: 2370 | Y7: 526 | Z7: 814 | AA7: 743 | AB7: 567 | AC7: 411 | AD7: 777 | AE7: 1935 | AF7: 867 | AG7: 861 | AH7: 396 | AI7: 362 | AJ7: 1634 | AK7: 1371 | AL7: 2345 | AM7: 1432 | AN7: 1134 | AO7: 1031 | AP7: 966 | AQ7: 913 | AR7: 1359 | AS7: 2570 | AT7: 3842 | AU7: 1683 | AV7: 2069 | AW7: 1507 | AX7: 1584 | AY7: 2184 | AZ7: 2696 | BA7: 1346 | BB7: 969 | BC7: 860 | BD7: 542 | BE7: 1353 | BF7: 855 | BG7: 2098 | BH7: 1455 | BI7: 3489 | BJ7: 1869 | BK7: 1674 | BL7: 923 | BM7: 3043 | BN7: 3333 | BO7: 1050 | BP7: 1098 | BQ7: 698 | BR7: 983 | BS7: 1079 | BT7: 970 | BU7: 2534 | BV7: 1555 | BW7: 8930 | BX7: 3135 | BY7: 3598 | BZ7: 4082 | CA7: 3581 | CB7: 4937 | CC7: 3629 | CD7: 3312 | CE7: 3459 | CF7: 3196 | CG7: 3370 | CH7: 3218 | CI7: 4102 | CJ7: 3603 | CK7: 3274 | CL7: 926 | CM7: 2571 | CN7: 3694 | CO7: 3543 | CP7: 4346 | CQ7: 4102 | CR7: 3459 | CS7: 3976 | CT7: 3666 | CU7: 3771 | CV7: 4119 | CW7: 4978 | CX7: 4001 | CY7: 3873 | CZ7: 3968 | DA7: 4767 | DB7: 9742 | DC7: 4371 | DD7: 4796 | DE7: 3076 | DF7: 2287 | DG7: 2845 | DH7: 2063 | DI7: 1893 | DJ7: 1906 | DK7: 2696 | DL7: 1910 | DM7: 1262 | DN7: 1910 | DO7: 1236 | DP7: 1589 | DQ7: 4535 | DR7: 4584 | DS7: 2591 | DT7: 2458 | DU7: 2323 | DV7: 2057 | DW7: 2452 | DX7: 2530 | DY7: 2270 | DZ7: 1705 | EA7: 1662 | EB7: 2363 | EC7: 4034 | ED7: 2377 | EE7: 3084 | EF7: 5716 | EG7: 3311 | EH7: 2940 | EI7: 2585 | EJ7: 3455 | EK7: 3319 | EL7: 2738 | EM7: 4807 | EN7: 3478 | EO7: 3362 | EP7: 2949 | EQ7: 2854 | ER7: 2790 | ES7: 4637 | ET7: 6537 | EU7: 2978 | EV7: 2437 | EW7: 3821 | EX7: 2587 | EY7: 2403 | EZ7: 5003 | FA7: 6060 | FB7: 4117 | FC7: 4020 | FD7: 2651 | FE7: 4178 | FF7: 4107 | FG7: 3756 | FH7: 5043 | FI7: 3223 | FJ7: 3705 | FK7: 5445 | FL7: 4173 | FM7: 3794 | FN7: 4128 | FO7: 4872 | FP7: 5669 | FQ7: 9276 | FR7: 10478 | FS7: 4186 | FT7: 3222 | FU7: 3434 | FV7: 4209 | FW7: 3696 | FX7: 3270 | FY7: 3756 | FZ7: 3944 | GA7: 3467 | GB7: 3216 | GC7: 3566 | GD7: 3246 | GE7: 3667 | GF7: 3990 | GG7: 3991 | GH7: 3374 | GI7: 4119 | GJ7: 5590 | GK7: 4685 | GL7: 3598 | GM7: 3301 | GN7: 3518 | GO7: 4100 | GP7: 5045 | GQ7: 5116 | GR7: 4711 | GS7: 3932 | GT7: 3692 | GU7: 4476 | GV7: 3588 | GW7: 3313 | GX7: 5467 | GY7: 5515 | GZ7: 4059 | HA7: 3327 | HB7: 4010 | HC7: 3502 | HD7: 2871 | HE7: 3727 | HF7: 2486 | HG7: 3740 | HH7: 3361 | HI7: 3271 | HJ7: 3637 | HK7: 3553 | HL7: 3968 | HM7: 3826 | HN7: 2698 | HO7: 2876 | HP7: 2935 | HQ7: 2841 | HR7: 2935 | HS7: 4098 | HT7: 2951 | HU7: 3357 | HV7: 3215 | HW7: 5363 | HX7: 3424 | HY7: 3371 | HZ7: 3482 | IA7: 4517 | IB7: 5508 | IC7: 3172 | ID7: 2353 | IE7: 3163 | IF7: 3463 | IG7: 4064 | IH7: 2537 | II7: 2606 | IJ7: 2206 | IK7: 2654 | IL7: 3772 | IM7: 2599 | IN7: 2460 | IO7: 2544 | IP7: 3499 | IQ7: 2862 | IR7: 2919 | IS7: 3992 | IT7: 4038 | IU7: 5424 | IV7: 4239 | IW7: 4246 | IX7: 3679 | IY7: 3469 | IZ7: 2897 | JA7: 3007 | JB7: 3412 | JC7: 1872 | JD7: 1970 | JE7: 1895 | JF7: 1840 | JG7: 2187 | JH7: 2246 | JI7: 4161 | JJ7: 3235 | JK7: 1880 | JL7: =JL5-JL6 -> 1547 | JM7: 2246 | JN7: 1388 | JO7: 2189 | JP7: 4065 | JQ7: 2814 | JR7: 1257 | JS7: 2339 | JT7: 1462 | JU7: 1213 | JV7: 1863 | JW7: 3783 | JX7: 2064 | JY7: 1330 | JZ7: 875 | KA7: 1516 | KB7: 1877 | KC7: 1779 | KD7: 3270 | KE7: 1429 | KF7: 1130 | KG7: 1351 | KH7: 1332 | KI7: 668 | KJ7: 2301 | KK7: 5335 | KL7: 3224 | KM7: 3101 | KN7: 3918 | KO7: 3191 | KP7: 3205 | KQ7: 2614 | KR7: 3679 | KS7: 1463 | KT7: 1360 | KU7: 1333 | KV7: 878 | KW7: 812 | KX7: 1352 | KY7: 3495 | LG7: 14455 | LH7: 13902 | LI7: 9667 | LJ7: 6827 | LK7: 8611 | LL7: 10608 | LM7: 12171 | LN7: 8351 | LO7: 8340 | LP7: 6433 | LQ7: 12922 | LR7: 12045 | LS7: 15034 | LT7: 13684 | LU7: 19420 | LV7: 18902 | LW7: 15192 | LX7: 13341 | LY7: 12646 | LZ7: 19270 | MA7: 13884 | MB7: 11653 | MC7: 8477 | MD7: 7016 | ME7: 6267 | MF7: 7609 | MG7: 11147 | MH7: 15191 | MI7: 15672 | MJ7: 8310 | MK7: 7632 | ML7: 5961 | MM7: 8027 | MN7: 6893 | MO7: 7007 | MP7: 6919 | MQ7: 5322 | MR7: 6838 | MS7: 4793 | MT7: 4814 | MU7: 5001 | MV7: 5486 | MW7: 3630 | MX7: 45727 | MY7: 46406 | MZ7: 11361 | NA7: 7133 | NB7: 11072 | NC7: 11611 | ND7: 9170 | NE7: 6434 | NF7: 7130 | NG7: 6950
F8: =F3 -> 45292 | G8: =G3 -> 45293 | H8: =H3 -> 45294 | I8: =I3 -> 45295 | J8: =J3 -> 45296 | K8: =K3 -> 45297 | L8: =L3 -> 45298 | M8: =M3 -> 45299 | ... NG8: =NG3 -> 31-12
B9: Percent Calls Handled | C9: =AVERAGE(F9:XA9) -> 0.73475989 | D9: =LOOKUP(2,1/(F9:XA9<>""),F9:XA9) -> 0.47877606 | E9: =1-D9 -> 0.52122394 | F9: =IFERROR(F6/F5,"") -> 0.93366209 | G9: =IFERROR(G6/G5,"") -> 0.95300081 | H9: =IFERROR(H6/H5,"") -> 0.93909217 | I9: =IFERROR(I6/I5,"") -> 0.95112782 | J9: =IFERROR(J6/J5,"") -> 0.82963141 | K9: =IFERROR(K6/K5,"") -> 0.83347165 | L9: =IFERROR(L6/L5,"") -> 0.94188912 | M9: =IFERROR(M6/M5,"") -> 0.9234239 | ... HR9: =IFERROR(HR6/HR5,"") -> 7.5647339 | HS9: =IFERROR(HS7/HS6,"") -> 0.68039183 | HT9: =IFERROR(HT6/HT5,"") -> 0.75837223 | HU9: =IFERROR(HU6/HU5,"") -> 0.7335555 | HV9: =IFERROR(HV6/HV5,"") -> 0.74790245 | HW9: =IFERROR(HW6/HW5,"") -> 0.72385747 | HX9: =IFERROR(HX6/HX5,"") -> 0.72069134 | HY9: =IFERROR(HY6/HY5,"") -> 0.72187397 | HZ9: =IFERROR(HZ6/HZ5,"") -> 0.64191691 | IA9: =IFERROR(IA6/IA5,"") -> 0.66426395 | ... KD9: =IFERROR(KD6/KD5,"") -> 0.67918423 | KE9: =IFERROR(KF6/KF5,"") -> 0.88661654 | KF9: =IFERROR(KG6/KG5,"") -> 0.85973837 | KG9: =IFERROR(KH6/KH5,"") -> 0.87111111 | KH9: =IFERROR(KI6/KI5,"") -> 0.92758808 | KI9: =IFERROR(KJ6/KJ5,"") -> 0.7981756 | KJ9: =IFERROR(KK6/KK5,"") -> 0.59290618 | KK9: =IFERROR(KK6/KK5,"") -> 0.59290618 | KL9: =IFERROR(KL6/KL5,"") -> 0.79580986 | KM9: =IFERROR(KM6/KM5,"") -> 0.81342879 | KN9: =IFERROR(KN6/KN5,"") -> 0.77080411 | KO9: =IFERROR(KO6/KO5,"") -> 0.80082366 | KP9: =IFERROR(KP6/KP5,"") -> 0.7814777 | KQ9: =IFERROR(KQ6/KQ5,"") -> 0.80391422 | KR9: =IFERROR(KR6/KR5,"") -> 0.67007555 | ... NG9: =IFERROR(NG6/NG5,"") -> 0.47877606
B10: Calls Handled in Service Level 20 sec | C10: =INT(AVERAGE(F10:LI10)) -> 6204 | D10: =LOOKUP(2,1/(F10:XA10<>""),F10:XA10) -> 3233 | F10: 7253 | G10: 7836 | H10: 7647 | I10: 8409 | J10: 6136 | K10: 8082 | L10: 8562 | M10: 7921 | N10: 8182 | O10: 8625 | P10: 8146 | Q10: 6510 | R10: 8363 | S10: 8695 | T10: 8443 | U10: 8698 | V10: 8361 | W10: 8760 | X10: 4903 | Y10: 8293 | Z10: 7621 | AA10: 7335 | AB10: 7427 | AC10: 7786 | AD10: 8151 | AE10: 5326 | AF10: 7759 | AG10: 7184 | AH10: 7320 | AI10: 7283 | AJ10: 6547 | AK10: 7688 | AL10: 5015 | AM10: 7438 | AN10: 7934 | AO10: 8912 | AP10: 9488 | AQ10: 9171 | AR10: 8491 | AS10: 4943 | AT10: 3780 | AU10: 6806 | AV10: 6013 | AW10: 6653 | AX10: 7237 | AY10: 7354 | AZ10: 5215 | BA10: 9200 | BB10: 9499 | BC10: 9115 | BD10: 9870 | BE10: 8198 | BF10: 8835 | BG10: 5341 | BH10: 7870 | BI10: 4728 | BJ10: 7749 | BK10: 7610 | BL10: 8900 | BM10: 5411 | BN10: 4053 | BP10: 8452 | BQ10: 7765 | BR10: 8485 | BS10: 6983 | BT10: 7575 | BU10: 4419 | BV10: 6675 | BW10: 1017 | BX10: 7298 | BY10: 4059 | BZ10: 4665 | CA10: 4782 | CB10: 3647 | CC10: 4578 | CD10: 5442 | CE10: 5152 | CF10: 6105 | CG10: 5903 | CH10: 6003 | CI10: 4985 | CJ10: 5521 | CK10: 5878 | CL10: 2952 | CM10: 3461 | CN10: 6378 | CO10: 6350 | CP10: 4968 | CQ10: 5572 | CR10: 6439 | CS10: 5099 | CT10: 5942 | CU10: 6172 | CV10: 5796 | CW10: 4616 | CX10: 5062 | CY10: 6334 | CZ10: 6005 | DA10: 1077 | DB10: 1749 | DC10: 3046 | DD10: 3080 | DE10: 7075 | DF10: 8015 | DG10: 7944 | DH10: 8163 | DI10: 7968 | DJ10: 7484 | DK10: 4795 | DL10: 7402 | DM10: 7401 | DN10: 7426 | DO10: 8092 | DP10: 7446 | DQ10: 4669 | DR10: 3617 | DS10: 7926 | DT10: 7809 | DU10: 7388 | DV10: 8025 | DW10: 7072 | DX10: 6067 | DY10: 5113 | DZ10: 7050 | EA10: 7512 | EB10: 6160 | EC10: 4305 | ED10: 5789 | EE10: 5348 | EF10: 2249 | EG10: 5295 | EH10: 5422 | EI10: 6538 | EJ10: 4750 | EK10: 4997 | EL10: 6578 | EM10: 1522 | EN10: 6130 | EO10: 4946 | EP10: 5823 | EQ10: 5584 | ER10: 6806 | ES10: 6249 | ET10: 1495 | EU10: 6477 | EV10: 6564 | EW10: 7638 | EX10: 6941 | EY10: 7700 | EZ10: 3815 | FA10: 1022 | FB10: 4985 | FC10: 5126 | FD10: 6793 | FE10: 4976 | FF10: 4777 | FG10: 5266 | FH10: 1283 | FI10: 6085 | FJ10: 6164 | FK10: 6404 | FL10: 6333 | FM10: 6216 | FN10: 6107 | FO10: 4332 | FP10: 5320 | FQ10: 0 | FR10: 0 | FS10: 5743 | FT10: 6053 | FU10: 6879 | FV10: 3883 | FW10: 6178 | FX10: 7061 | FY10: 6241 | FZ10: 5832 | GA10: 5828 | GB10: 6552 | GC10: 4772 | GD10: 6023 | GE10: 6298 | GF10: 6112 | GG10: 6701 | GH10: 7555 | GI10: 5771 | GJ10: 3200 | GK10: 6314 | GL10: 7569 | GM10: 8054 | GN10: 8054 | GO10: 3734 | GP10: 3066 | GQ10: 6404 | GR10: 8039 | GS10: 7880 | GT10: 6621 | GU10: 7948 | GV10: 8342 | GW10: 3485 | GX10: 5241 | GY10: 5241 | GZ10: 7414 | HA10: 7366 | HB10: 6308 | HC10: 6939 | HD10: 8150 | HE10: 4359 | HF10: 7797 | HG10: 7339 | HH10: 7591 | HI10: 7570 | HJ10: 6628 | HK10: 6822 | HL10: 3509 | HM10: 5977 | HN10: 6524 | HO10: 6232 | HP10: 6822 | HQ10: 6912 | HR10: 6942 | HS10: 3486 | HT10: 6738 | HU10: 6188 | HV10: 6123 | HW10: 5819 | HX10: 5182 | HY10: 5612 | HZ10: 3583 | IA10: 4216 | IB10: 4559 | IC10: 6278 | ID10: 5723 | IE10: 5973 | IF10: 5146 | IG10: 5164 | IH10: 5780 | II10: 6111 | IJ10: 6135 | IK10: 6017 | IL10: 5110 | IM10: 6245 | IN10: 5265 | IO10: 5651 | IP10: 5359 | IQ10: 5792 | IR10: 5876 | IS10: 5041 | IT10: 5057 | IU10: 1709 | IV10: 5487 | IW10: 5137 | IX10: 5926 | IY10: 6172 | IZ10: 6434 | JA10: 6535 | JB10: 3642 | JC10: 6104 | JD10: 6041 | JE10: 6025 | JF10: 6681 | JG10: 6447 | JH10: 7399 | JI10: 2716 | JJ10: 5586 | JK10: 6993 | JL10: 6883 | JM10: 7022 | JN10: 6449 | JO10: 5844 | JP10: 3412 | JQ10: 5455 | JR10: 6627 | JS10: 5790 | JT10: 6842 | JU10: 6964 | JV10: 6738 | JW10: 3350 | JX10: 6545 | JY10: 6622 | JZ10: 6328 | KA10: 7637 | KB10: 7143 | KC10: 8226 | KD10: 4886 | KE10: 7775 | KF10: 7652 | KG10: 6946 | KH10: 7425 | KI10: 7497 | KJ10: 6898 | KK10: 2871 | KL10: 8522 | KM10: 8855 | KN10: 5391 | KO10: 8473 | KP10: 6967 | KQ10: 7936 | KR10: 4292 | KS10: 7904 | KT10: 7583 | KU10: 7349 | KV10: 7609 | KW10: 7423 | KX10: 7424 | KY10: 3233
B11: Percent Service Level in 20 sec | C11: =AVERAGE(F11:LI11) -> 0.58578276 | D11: =LOOKUP(2,1/(F11:XA11<>""),F11:XA11) -> 0 | F11: =IFERROR(F10/F5,"") -> 0.85159094 | G11: =IFERROR(G10/G5,"") -> 0.90266098 | H11: =IFERROR(H10/H5,"") -> 0.88547939 | I11: =IFERROR(I10/I5,"") -> 0.90322234 | J11: =IFERROR(J10/J5,"") -> 0.73670309 | K11: =IFERROR(K10/K5,"") -> 0.74522822 | L11: =IFERROR(L10/L5,"") -> 0.87905544 | M11: =IFERROR(M10/M5,"") -> 0.83090318 | ... HR11: =IFERROR(HR10/HR5,"") -> 5.5138999 | HS11: =IFERROR(HS10/HS6,"") -> 0.57878134 | HT11: =IFERROR(HT10/HT5,"") -> 0.5517072 | HU11: =IFERROR(HU10/HU5,"") -> 0.49099421 | HV11: =IFERROR(HV10/HV5,"") -> 0.48012232 | HW11: =IFERROR(HW10/HW5,"") -> 0.45073586 | HX11: =IFERROR(HX10/HX5,"") -> 0.42246861 | HY11: =IFERROR(HY10/HY5,"") -> 0.46288354 | HZ11: =IFERROR(HZ10/HZ5,"") -> 0.36846977 | IA11: =IFERROR(IA10/IA5,"") -> 0.3132942 | ... JT11: =IFERROR(JT10/JT5,"") -> 0.68950922 | JU11: =IFERROR(JU10/JU6,"") -> 0.84720195 | JV11: =IFERROR(JV10/JV5,"") -> 0.65646921 | JW11: =IFERROR(JW10/JW5,"") -> 0.35226078 | JX11: =IFERROR(JX10/JX5,"") -> 0.61082594 | JY11: =IFERROR(JY10/JY5,"") -> 0.69624645 | JZ11: =IFERROR(JZ10/JZ5,"") -> 0.77378332 | KA11: =IFERROR(KA10/KA5,"") -> 0.73687765 | KB11: =IFERROR(KB10/KB6,"") -> 0.78823659 | KC11: =IFERROR(KC10/KC5,"") -> 0.72221247 | KD11: =IFERROR(KD10/KD5,"") -> 0.47906658 | KE11: =IFERROR(KE10/KF5,"") -> 0.77944862 | KF11: =IFERROR(KF10/KG5,"") -> 0.79443522 | KG11: =IFERROR(KG10/KH5,"") -> 0.67111111 | KH11: =IFERROR(KH10/KI5,"") -> 0.80487805 | KI11: =IFERROR(KI10/KJ5,"") -> 0.6575739 | KJ11: =IFERROR(KJ10/KK5,"") -> 0.52616323 | KK11: =IFERROR(KK10/KK5,"") -> 0.21899314 | KL11: =IFERROR(KL10/KL5,"") -> 0.53940123 | KM11: =IFERROR(KM10/KM5,"") -> 0.53275976 | KN11: =IFERROR(KN10/KN5,"") -> 0.31504208 | KO11: =IFERROR(KO10/KO5,"") -> 0.52870336 | KP11: =IFERROR(KP10/KP5,"") -> 0.47442969 | KQ11: =IFERROR(KQ10/KQ5,"") -> 0.59508098 | KR11: =IFERROR(KR10/KR5,"") -> 0.39543026 | ... NG11: =IFERROR(NG10/NG5,"") -> 0
B12: Target of Percent Calls Handled | F12: 0.95 | G12: 0.95 | H12: 0.95 | I12: 0.95 | J12: 0.95 | K12: 0.95 | L12: 0.95 | M12: 0.95 | N12: 0.95 | O12: 0.95 | P12: 0.95 | Q12: 0.95 | R12: 0.95 | S12: 0.95 | T12: 0.95 | U12: 0.95 | V12: 0.95 | W12: 0.95 | X12: 0.95 | Y12: 0.95 | Z12: 0.95 | AA12: 0.95 | AB12: 0.95 | AC12: 0.95 | AD12: 0.95 | AE12: 0.95 | AF12: 0.95 | AG12: 0.95 | AH12: 0.95 | AI12: 0.95 | AJ12: 0.95 | AK12: 0.95 | AL12: 0.95 | AM12: 0.95 | AN12: 0.95 | AO12: 0.95 | AP12: 0.95 | AQ12: 0.95 | AR12: 0.95 | AS12: 0.95 | AT12: 0.95 | AU12: 0.95 | AV12: 0.95 | AW12: 0.95 | AX12: 0.95 | AY12: 0.95 | AZ12: 0.95 | BA12: 0.95 | BB12: 0.95 | BC12: 0.95 | BD12: 0.95 | BE12: 0.95 | BF12: 0.95 | BG12: 0.95 | BH12: 0.95 | BI12: 0.95 | BJ12: 0.95 | BK12: 0.95 | BL12: 0.95 | BM12: 0.95 | BN12: 0.95 | BO12: 0.95 | BP12: 0.95 | BQ12: 0.95 | BR12: 0.95 | BS12: 0.95 | BT12: 0.95 | BU12: 0.95 | BV12: 0.95 | BW12: 0.95 | BX12: 0.95 | BY12: 0.95 | BZ12: 0.95 | CA12: 0.95 | CB12: 0.95 | CC12: 0.95 | CD12: 0.95 | CE12: 0.95 | CF12: 0.95 | CG12: 0.95 | CH12: 0.95 | CI12: 0.95 | CJ12: 0.95 | CK12: 0.95 | CL12: 0.95 | CM12: 0.95 | CN12: 0.95 | CO12: 0.95 | CP12: 0.95 | CQ12: 0.95 | CR12: 0.95 | CS12: 0.95 | CT12: 0.95 | CU12: 0.95 | CV12: 0.95 | CW12: 0.95 | CX12: 0.95 | CY12: 0.95 | CZ12: 0.95 | DA12: 0.95 | DB12: 0.95 | DC12: 0.95 | DD12: 0.95 | DE12: 0.95 | DF12: 0.95 | DG12: 0.95 | DH12: 0.95 | DI12: 0.95 | DJ12: 0.95 | DK12: 0.95 | DL12: 0.95 | DM12: 0.95 | DN12: 0.95 | DO12: 0.95 | DP12: 0.95 | DQ12: 0.95 | DR12: 0.95 | DS12: 0.95 | DT12: 0.95 | DU12: 0.95 | DV12: 0.95 | DW12: 0.95 | DX12: 0.95 | DY12: 0.95 | DZ12: 0.95 | EA12: 0.95 | EB12: 0.95 | EC12: 0.95 | ED12: 0.95 | EE12: 0.95 | EF12: 0.95 | EG12: 0.95 | EH12: 0.95 | EI12: 0.95 | EJ12: 0.95 | EK12: 0.95 | EL12: 0.95 | EM12: 0.95 | EN12: 0.95 | EO12: 0.95 | EP12: 0.95 | EQ12: 0.95 | ER12: 0.95 | ES12: 0.95 | ET12: 0.95 | EU12: 0.95 | EV12: 0.95 | EW12: 0.95 | EX12: 0.95 | EY12: 0.95 | EZ12: 0.95 | FA12: 0.95 | FB12: 0.95 | FC12: 0.95 | FD12: 0.95 | FE12: 0.95 | FF12: 0.95 | FG12: 0.95 | FH12: 0.95 | FI12: 0.95 | FJ12: 0.95 | FK12: 0.95 | FL12: 0.95 | FM12: 0.95 | FN12: 0.95 | FO12: 0.95 | FP12: 0.95 | FQ12: 0.95 | FR12: 0.95 | FS12: 0.95 | FT12: 0.95 | FU12: 0.95 | FV12: 0.95 | FW12: 0.95 | FX12: 0.95 | FY12: 0.95 | FZ12: 0.95 | GA12: 0.95 | GB12: 0.95 | GC12: 0.95 | GD12: 0.95 | GE12: 0.95 | GF12: 0.95 | GG12: 0.95 | GH12: 0.95 | GI12: 0.95 | GJ12: 0.95 | GK12: 0.95 | GL12: 0.95 | GM12: 0.95 | GN12: 0.95 | GO12: 0.95 | GP12: 0.95 | GQ12: 0.95 | GR12: 0.95 | GS12: 0.95 | GT12: 0.95 | GU12: 0.95 | GV12: 0.95 | GW12: 0.95 | GX12: 0.95 | GY12: 0.95 | GZ12: 0.95 | HA12: 0.95 | HB12: 0.95 | HC12: 0.95 | HD12: 0.95 | HE12: 0.95 | HF12: 0.95 | HG12: 0.95 | HH12: 0.95 | HI12: 0.95 | HJ12: 0.95 | HK12: 0.95 | HL12: 0.95 | HM12: 0.95 | HN12: 0.95 | HO12: 0.95 | HP12: 0.95 | HQ12: 0.95 | HR12: 0.95 | HS12: 0.95 | HT12: 0.95 | HU12: 0.95 | HV12: 0.95 | HW12: 0.95 | HX12: 0.95 | HY12: 0.95 | HZ12: 0.95 | IA12: 0.95 | IB12: 0.95 | IC12: 0.95 | ID12: 0.95 | IE12: 0.95 | IF12: 0.95 | IG12: 0.95 | IH12: 0.95 | II12: 0.95 | IJ12: 0.95 | IK12: 0.95 | IL12: 0.95 | IM12: 0.95 | IN12: 0.95 | IO12: 0.95 | IP12: 0.95 | IQ12: 0.95 | IR12: 0.95 | IS12: 0.95 | IT12: 0.95 | IU12: 0.95 | IV12: 0.95 | IW12: 0.95 | IX12: 0.95 | IY12: 0.95 | IZ12: 0.95 | JA12: 0.95 | JB12: 0.95 | JC12: 0.95 | JD12: 0.95 | JE12: 0.95 | JF12: 0.95 | JG12: 0.95 | JH12: 0.95 | JI12: 0.95 | JJ12: 0.95 | JK12: 0.95 | JL12: 0.95 | JM12: 0.95 | JN12: 0.95 | JO12: 0.95 | JP12: 0.95 | JQ12: 0.95 | JR12: 0.95 | JS12: 0.95 | JT12: 0.95 | JU12: 0.95 | JV12: 0.95 | JW12: 0.95 | JX12: 0.95 | JY12: 0.95 | JZ12: 0.95 | KA12: 0.95 | KB12: 0.95 | KC12: 0.95 | KD12: 0.95 | KE12: 0.95 | KF12: 0.95 | KG12: 0.95 | KH12: 0.95 | KI12: 0.95 | KJ12: 0.95 | KK12: 0.95 | KL12: 0.95 | KM12: 0.95 | KN12: 0.95 | KO12: 0.95 | KP12: 0.95 | KQ12: 0.95 | KR12: 0.95 | KS12: 0.95 | KT12: 0.95 | KU12: 0.95 | KV12: 0.95 | KW12: 0.95 | KX12: 0.95 | KY12: 0.95 | KZ12: 0.95 | LA12: 0.95 | LB12: 0.95 | LC12: 0.95 | LD12: 0.95 | LE12: 0.95 | LF12: 0.95 | LG12: 0.95 | LH12: 0.95 | LI12: 0.95 | LJ12: 0.95 | LK12: 0.95 | LL12: 0.95 | LM12: 0.95 | LN12: 0.95 | LO12: 0.95 | LP12: 0.95 | LQ12: 0.95 | LR12: 0.95 | LS12: 0.95 | LT12: 0.95 | LU12: 0.95 | LV12: 0.95 | LW12: 0.95 | LX12: 0.95 | LY12: 0.95 | LZ12: 0.95 | MA12: 0.95 | MB12: 0.95 | MC12: 0.95 | MD12: 0.95 | ME12: 0.95 | MF12: 0.95 | MG12: 0.95 | MH12: 0.95 | MI12: 0.95 | MJ12: 0.95 | MK12: 0.95 | ML12: 0.95 | MM12: 0.95 | MN12: 0.95 | MO12: 0.95 | MP12: 0.95 | MQ12: 0.95 | MR12: 0.95 | MS12: 0.95 | MT12: 0.95 | MU12: 0.95 | MV12: 0.95 | MW12: 0.95 | MX12: 0.95 | MY12: 0.95 | MZ12: 0.95 | NA12: 0.95 | NB12: 0.95 | NC12: 0.95 | ND12: 0.95 | NE12: 0.95 | NF12: 0.95 | NG12: 0.95
B13: Target of Percent Service Level in 20 sec | F13: 0.85 | G13: 0.85 | H13: 0.85 | I13: 0.85 | J13: 0.85 | K13: 0.85 | L13: 0.85 | M13: 0.85 | N13: 0.85 | O13: 0.85 | P13: 0.85 | Q13: 0.85 | R13: 0.85 | S13: 0.85 | T13: 0.85 | U13: 0.85 | V13: 0.85 | W13: 0.85 | X13: 0.85 | Y13: 0.85 | Z13: 0.85 | AA13: 0.85 | AB13: 0.85 | AC13: 0.85 | AD13: 0.85 | AE13: 0.85 | AF13: 0.85 | AG13: 0.85 | AH13: 0.85 | AI13: 0.85 | AJ13: 0.85 | AK13: 0.85 | AL13: 0.85 | AM13: 0.85 | AN13: 0.85 | AO13: 0.85 | AP13: 0.85 | AQ13: 0.85 | AR13: 0.85 | AS13: 0.85 | AT13: 0.85 | AU13: 0.85 | AV13: 0.85 | AW13: 0.85 | AX13: 0.85 | AY13: 0.85 | AZ13: 0.85 | BA13: 0.85 | BB13: 0.85 | BC13: 0.85 | BD13: 0.85 | BE13: 0.85 | BF13: 0.85 | BG13: 0.85 | BH13: 0.85 | BI13: 0.85 | BJ13: 0.85 | BK13: 0.85 | BL13: 0.85 | BM13: 0.85 | BN13: 0.85 | BO13: 0.85 | BP13: 0.85 | BQ13: 0.85 | BR13: 0.85 | BS13: 0.85 | BT13: 0.85 | BU13: 0.85 | BV13: 0.85 | BW13: 0.85 | BX13: 0.85 | BY13: 0.85 | BZ13: 0.85 | CA13: 0.85 | CB13: 0.85 | CC13: 0.85 | CD13: 0.85 | CE13: 0.85 | CF13: 0.85 | CG13: 0.85 | CH13: 0.85 | CI13: 0.85 | CJ13: 0.85 | CK13: 0.85 | CL13: 0.85 | CM13: 0.85 | CN13: 0.85 | CO13: 0.85 | CP13: 0.85 | CQ13: 0.85 | CR13: 0.85 | CS13: 0.85 | CT13: 0.85 | CU13: 0.85 | CV13: 0.85 | CW13: 0.85 | CX13: 0.85 | CY13: 0.85 | CZ13: 0.85 | DA13: 0.85 | DB13: 0.85 | DC13: 0.85 | DD13: 0.85 | DE13: 0.85 | DF13: 0.85 | DG13: 0.85 | DH13: 0.85 | DI13: 0.85 | DJ13: 0.85 | DK13: 0.85 | DL13: 0.85 | DM13: 0.85 | DN13: 0.85 | DO13: 0.85 | DP13: 0.85 | DQ13: 0.85 | DR13: 0.85 | DS13: 0.85 | DT13: 0.85 | DU13: 0.85 | DV13: 0.85 | DW13: 0.85 | DX13: 0.85 | DY13: 0.85 | DZ13: 0.85 | EA13: 0.85 | EB13: 0.85 | EC13: 0.85 | ED13: 0.85 | EE13: 0.85 | EF13: 0.85 | EG13: 0.85 | EH13: 0.85 | EI13: 0.85 | EJ13: 0.85 | EK13: 0.85 | EL13: 0.85 | EM13: 0.85 | EN13: 0.85 | EO13: 0.85 | EP13: 0.85 | EQ13: 0.85 | ER13: 0.85 | ES13: 0.85 | ET13: 0.85 | EU13: 0.85 | EV13: 0.85 | EW13: 0.85 | EX13: 0.85 | EY13: 0.85 | EZ13: 0.85 | FA13: 0.85 | FB13: 0.85 | FC13: 0.85 | FD13: 0.85 | FE13: 0.85 | FF13: 0.85 | FG13: 0.85 | FH13: 0.85 | FI13: 0.85 | FJ13: 0.85 | FK13: 0.85 | FL13: 0.85 | FM13: 0.85 | FN13: 0.85 | FO13: 0.85 | FP13: 0.85 | FQ13: 0.85 | FR13: 0.85 | FS13: 0.85 | FT13: 0.85 | FU13: 0.85 | FV13: 0.85 | FW13: 0.85 | FX13: 0.85 | FY13: 0.85 | FZ13: 0.85 | GA13: 0.85 | GB13: 0.85 | GC13: 0.85 | GD13: 0.85 | GE13: 0.85 | GF13: 0.85 | GG13: 0.85 | GH13: 0.85 | GI13: 0.85 | GJ13: 0.85 | GK13: 0.85 | GL13: 0.85 | GM13: 0.85 | GN13: 0.85 | GO13: 0.85 | GP13: 0.85 | GQ13: 0.85 | GR13: 0.85 | GS13: 0.85 | GT13: 0.85 | GU13: 0.85 | GV13: 0.85 | GW13: 0.85 | GX13: 0.85 | GY13: 0.85 | GZ13: 0.85 | HA13: 0.85 | HB13: 0.85 | HC13: 0.85 | HD13: 0.85 | HE13: 0.85 | HF13: 0.85 | HG13: 0.85 | HH13: 0.85 | HI13: 0.85 | HJ13: 0.85 | HK13: 0.85 | HL13: 0.85 | HM13: 0.85 | HN13: 0.85 | HO13: 0.85 | HP13: 0.85 | HQ13: 0.85 | HR13: 0.85 | HS13: 0.85 | HT13: 0.85 | HU13: 0.85 | HV13: 0.85 | HW13: 0.85 | HX13: 0.85 | HY13: 0.85 | HZ13: 0.85 | IA13: 0.85 | IB13: 0.85 | IC13: 0.85 | ID13: 0.85 | IE13: 0.85 | IF13: 0.85 | IG13: 0.85 | IH13: 0.85 | II13: 0.85 | IJ13: 0.85 | IK13: 0.85 | IL13: 0.85 | IM13: 0.85 | IN13: 0.85 | IO13: 0.85 | IP13: 0.85 | IQ13: 0.85 | IR13: 0.85 | IS13: 0.85 | IT13: 0.85 | IU13: 0.85 | IV13: 0.85 | IW13: 0.85 | IX13: 0.85 | IY13: 0.85 | IZ13: 0.85 | JA13: 0.85 | JB13: 0.85 | JC13: 0.85 | JD13: 0.85 | JE13: 0.85 | JF13: 0.85 | JG13: 0.85 | JH13: 0.85 | JI13: 0.85 | JJ13: 0.85 | JK13: 0.85 | JL13: 0.85 | JM13: 0.85 | JN13: 0.85 | JO13: 0.85 | JP13: 0.85 | JQ13: 0.85 | JR13: 0.85 | JS13: 0.85 | JT13: 0.85 | JU13: 0.85 | JV13: 0.85 | JW13: 0.85 | JX13: 0.85 | JY13: 0.85 | JZ13: 0.85 | KA13: 0.85 | KB13: 0.85 | KC13: 0.85 | KD13: 0.85 | KE13: 0.85 | KF13: 0.85 | KG13: 0.85 | KH13: 0.85 | KI13: 0.85 | KJ13: 0.85 | KK13: 0.85 | KL13: 0.85 | KM13: 0.85 | KN13: 0.85 | KO13: 0.85 | KP13: 0.85 | KQ13: 0.85 | KR13: 0.85 | KS13: 0.85 | KT13: 0.85 | KU13: 0.85 | KV13: 0.85 | KW13: 0.85 | KX13: 0.85 | KY13: 0.85 | KZ13: 0.85 | LA13: 0.85 | LB13: 0.85 | LC13: 0.85 | LD13: 0.85 | LE13: 0.85 | LF13: 0.85 | LG13: 0.85 | LH13: 0.85 | LI13: 0.85 | LJ13: 0.85 | LK13: 0.85 | LL13: 0.85 | LM13: 0.85 | LN13: 0.85 | LO13: 0.85 | LP13: 0.85 | LQ13: 0.85 | LR13: 0.85 | LS13: 0.85 | LT13: 0.85 | LU13: 0.85 | LV13: 0.85 | LW13: 0.85 | LX13: 0.85 | LY13: 0.85 | LZ13: 0.85 | MA13: 0.85 | MB13: 0.85 | MC13: 0.85 | MD13: 0.85 | ME13: 0.85 | MF13: 0.85 | MG13: 0.85 | MH13: 0.85 | MI13: 0.85 | MJ13: 0.85 | MK13: 0.85 | ML13: 0.85 | MM13: 0.85 | MN13: 0.85 | MO13: 0.85 | MP13: 0.85 | MQ13: 0.85 | MR13: 0.85 | MS13: 0.85 | MT13: 0.85 | MU13: 0.85 | MV13: 0.85 | MW13: 0.85 | MX13: 0.85 | MY13: 0.85 | MZ13: 0.85 | NA13: 0.85 | NB13: 0.85 | NC13: 0.85 | ND13: 0.85 | NE13: 0.85 | NF13: 0.85 | NG13: 0.85
D14: Avg-Calls Handled per Month | E14: Target
B15: Percent Calls Handled per Month | C15: Jan | D15: =IFERROR(AVERAGE(F9:AJ9),0) -> 0.90519201 | E15: 0.95
C16: Feb | D16: =IFERROR(AVERAGE(AK9:BL9),0) -> 0.8219999 | E16: 0.95
C17: Mar | D17: =IFERROR(AVERAGE(BM9:CQ9),0) -> 0.68299729 | E17: 0.95
C18: Apr | D18: =IFERROR(AVERAGE(CR9:DU9),0) -> 0.6798014 | E18: 0.95
C19: May | D19: =IFERROR(AVERAGE(DV9:EZ9),0) -> 0.98651119 | E19: 0.95
C20: Jun | D20: =IFERROR(AVERAGE(FA9:GD9),0) -> 0.62776073 | E20: 0.95
C21: Jul | D21: =IFERROR(AVERAGE(GE9:HI9),0) -> 0.69646053 | E21: 0.95
C22: Aug | D22: =IFERROR((AVERAGE(HJ9:IN9)),0) -> 0.94070732 | E22: 0.95
C23: Sep | D23: =IFERROR(AVERAGE(IO9:JR9),0) -> 0.74481563 | E23: 0.95
C24: Oct | D24: =IFERROR(AVERAGE(JS9:KW9),0) -> 0.80877891 | E24: 0.95
C25: Nov | D25: =IFERROR(AVERAGE(KX9:MA9),0) -> 0.39640459 | E25: 0.95
C26: Dec | D26: =IFERROR(AVERAGE(MB9:NF9),0) -> 0.45017177 | E26: 0.95
C27: Avg | D27: Last Rec | F27: =F3 -> 45292 | G27: =G3 -> 45293 | H27: =H3 -> 45294 | I27: =I3 -> 45295 | J27: =J3 -> 45296 | K27: =K3 -> 45297 | L27: =L3 -> 45298 | M27: =M3 -> 45299 | ... NG27: =NG3 -> 31-12
B28: Avg Handle Time | C28: =AVERAGE(F28:LI28) -> 0.0012515179 | D28: =LOOKUP(2,1/(F28:XA28<>""),F28:XA28) -> 0.0012847222 | F28: 0.0011921296 | G28: 0.00125 | H28: 0.0012731481 | I28: 0.0012268519 | J28: 0.0011805556 | K28: 0.0011921296 | L28: 0.0012268519 | M28: 0.0012037037 | N28: 0.0012152778 | O28: 0.0011921296 | P28: 0.00125 | Q28: 0.0011574074 | R28: 0.00125 | S28: 0.00125 | T28: 0.0012268519 | U28: 0.0012037037 | V28: 0.0012037037 | W28: 0.0011574074 | X28: 0.0011574074 | Y28: 0.0012037037 | Z28: 0.0012384259 | AA28: 0.0012384259 | AB28: 0.0012384259 | AC28: 0.0012268519 | AD28: 0.0012731481 | AE28: 0.0011458333 | AF28: 0.0012037037 | AG28: 0.0012384259 | AH28: 0.0012268519 | AI28: 0.0012384259 | AJ28: 0.00125 | AK28: 0.0012384259 | AL28: 0.0011458333 | AM28: 0.00125 | AN28: 0.0012152778 | AO28: 0.0012152778 | AP28: 0.0011921296 | AQ28: 0.0011805556 | AR28: 0.0011921296 | AS28: 0.0010763889 | AT28: 0.0012615741 | AU28: 0.00125 | AV28: 0.0013078704 | AW28: 0.0012384259 | AX28: 0.0012268519 | AY28: 0.0012037037 | AZ28: 0.0011458333 | BA28: 0.0011111111 | BB28: 0.0011342593 | BC28: 0.0012152778 | BD28: 0.0011921296 | BE28: 0.0011921296 | BF28: 0.0011574074 | BG28: 0.0010648148 | BH28: 0.0011111111 | BI28: 0.0012847222 | BJ28: 0.0011342593 | BK28: 0.0011805556 | BL28: 0.0011805556 | BM28: 0.0012615741 | BN28: 0.0011574074 | BO28: 0.0011921296 | BP28: 0.0011689815 | BQ28: 0.0011805556 | BR28: 0.0011342593 | BS28: 0.0012268519 | BT28: 0.0012384259 | BU28: 0.0011458333 | BV28: 0.0012152778 | BW28: 0.0012615741 | BX28: 0.0013078704 | BY28: 0.0012615741 | BZ28: 0.0012962963 | CA28: 0.0012615741 | CB28: 0.0013657407 | CC28: 0.0013310185 | CD28: 0.0012731481 | CE28: 0.0012962963 | CF28: 0.0012615741 | CG28: 0.0012615741 | CH28: 0.0012384259 | CI28: 0.0012268519 | CJ28: 0.0012152778 | CK28: 0.0012152778 | CL28: 0.0013888889 | CM28: 0.0012268519 | CN28: 0.0011921296 | CO28: 0.0012037037 | CP28: 0.0012152778 | CQ28: 0.0012152778 | CR28: 0.0012037037 | CS28: 0.00125 | CT28: 0.0012268519 | CU28: 0.0012152778 | CV28: 0.0012152778 | CW28: 0.0012152778 | CX28: 0.0012268519 | CY28: 0.0011574074 | CZ28: 0.0011689815 | DA28: 0.0011342593 | DB28: 0.0011921296 | DC28: 0.0012731481 | DD28: 0.00125 | DE28: 0.0012152778 | DF28: 0.0012615741 | DG28: 0.0012268519 | DH28: 0.00125 | DI28: 0.0012152778 | DJ28: 0.0012268519 | DK28: 0.0011921296 | DL28: 0.0012037037 | DM28: 0.0011921296 | DN28: 0.0011574074 | DO28: 0.0011458333 | DP28: 0.0011689815 | DQ28: 0.0011805556 | DR28: 0.0011574074 | DS28: 0.0011805556 | DT28: 0.0011689815 | DU28: 0.0011805556 | DV28: 0.0011458333 | DW28: 0.0011689815 | DX28: 0.0011689815 | DY28: 0.0011342593 | DZ28: 0.0011342593 | EA28: 0.0011458333 | EB28: 0.0012268519 | EC28: 0.0012268519 | ED28: 0.0012152778 | EE28: 0.0012268519 | EF28: 0.00125 | EG28: 0.0012731481 | EH28: 0.0012268519 | EI28: 0.0012152778 | EJ28: 0.0012962963 | EK28: 0.0012962963 | EL28: 0.0012152778 | EM28: 0.0013194444 | EN28: 0.0013310185 | EO28: 0.0013425926 | EP28: 0.0013078704 | EQ28: 0.0012152778 | ER28: 0.0012384259 | ES28: 0.0011805556 | ET28: 0.0012731481 | EU28: 0.0012384259 | EV28: 0.0012268519 | EW28: 0.0011342593 | EX28: 0.0011805556 | EY28: 0.0011689815 | EZ28: 0.0012615741 | FA28: 0.0013425926 | FB28: 0.0012731481 | FC28: 0.0012268519 | FD28: 0.0011921296 | FE28: 0.0011921296 | FF28: 0.0012268519 | FG28: 0.0012268519 | FH28: 0.0012152778 | FI28: 0.0012384259 | FJ28: 0.0011574074 | FK28: 0.0011921296 | FL28: 0.0011921296 | FM28: 0.0012615741 | FN28: 0.0012847222 | FO28: 0.0012731481 | FP28: 0.0012037037 | FQ28: 0.0010763889 | FR28: 0 | FS28: 0.0012615741 | FT28: 0.0012037037 | FU28: 0.00125 | FV28: 0.0012152778 | FW28: 0.0012152778 | FX28: 0.0012152778 | FY28: 0.0012615741 | FZ28: 0.0012615741 | GA28: 0.0012731481 | GB28: 0.0012268519 | GC28: 0.0011458333 | GD28: 0.0012847222 | GE28: 0.0013078704 | GF28: 0.0013425926 | GG28: 0.0013425926 | GH28: 0.0012962963 | GI28: 0.0013078704 | GJ28: 0.0012962963 | GK28: 0.0013425926 | GL28: 0.0012962963 | GM28: 0.0012962963 | GN28: 0.0013425926 | GO28: 0.001412037 | GP28: 0.0012615741 | GQ28: 0.0013310185 | GR28: 0.0013310185 | GS28: 0.0013310185 | GT28: 0.0013078704 | GU28: 0.0013194444 | GV28: 0.0012731481 | GW28: 0.0013425926 | GX28: 0.0013888889 | GY28: 0.0013888889 | GZ28: 0.0013194444 | HA28: 0.00125 | HB28: 0.0012847222 | HC28: 0.0012615741 | HD28: 0.0012384259 | HE28: 0.0012615741 | HF28: 0.0012731481 | HG28: 0.0012962963 | HH28: 0.0013078704 | HI28: 0.0012731481 | HJ28: 0.0012962963 | HK28: 0.0012615741 | HL28: 0.0012731481 | HM28: 0.0012615741 | HN28: 0.0012615741 | HO28: 0.0012384259 | HP28: 0.0012847222 | HQ28: 0.00125 | HR28: 0.0012615741 | HS28: 0.00125 | HT28: 0.0012847222 | HU28: 0.0012615741 | HV28: 0.0012615741 | HW28: 0.0013078704 | HX28: 0.0012615741 | HY28: 0.0012847222 | HZ28: 0.00125 | IA28: 0.0014351852 | IB28: 0.001400463 | IC28: 0.0012847222 | ID28: 0.0012962963 | IE28: 0.0013078704 | IF28: 0.0013425926 | IG28: 0.0013425926 | IH28: 0:1;53 | II28: 0.0012847222 | IJ28: 0.0012615741 | IK28: 0.0012962963 | IL28: 0.0013425926 | IM28: 0.0012731481 | IN28: 0.0012268519 | IO28: 0.0012847222 | IP28: 0.0013657407 | IQ28: 0.0013657407 | IR28: 0.0013194444 | IS28: 0.0013425926 | IT28: 0.0013078704 | IU28: 0.0012962963 | IV28: 0.0013541667 | IW28: 0.0013078704 | IX28: 0.0012847222 | IY28: 0.0013773148 | IZ28: 0.0013194444 | JA28: 0.0013078704 | JB28: 0.0012731481 | JC28: 0.0013194444 | JD28: 0.00125 | JE28: 0.0012962963 | JF28: 0.0013078704 | JG28: 0.0013310185 | JH28: 0.0013310185 | JI28: 0.0012847222 | JJ28: 0.0013310185 | JK28: 0.0013773148 | JL28: 0.0013425926 | JM28: 0.0013657407 | JN28: 0.0013194444 | JO28: 0.0013078704 | JP28: 0.00125 | JQ28: 0.0013425926 | JR28: 0.0013310185 | JS28: 0.0014583333 | JT28: 0.0013657407 | JU28: 0.001400463 | JV28: 0.0013425926 | JW28: 0.0013310185 | JX28: 0.0013657407 | JY28: 0.0013773148 | JZ28: 0.0014236111 | KA28: 0.001400463 | KB28: 0.0013657407 | KC28: 0.0013194444 | KD28: 0.00125 | KE28: 0.0013194444 | KF28: 0.0013657407 | KG28: 0.0013425926 | KH28: 0.0013541667 | KI28: 0.0013657407 | KJ28: 0.0013425926 | KK28: 0.0012962963 | KL28: 0.0012384259 | KM28: 0.0012384259 | KN28: 0.0012384259 | KO28: 0.0012962963 | KP28: 0.0012847222 | KQ28: 0.0013078704 | KR28: 0.0012615741 | KS28: 0.0012731481 | KT28: 0.0013078704 | KU28: 0.0013078704 | KV28: 0.0012962963 | KW28: 0.0013078704 | KX28: 0.0013194444 | KY28: 0.0012847222
B29: Max Handle Time | C29: =AVERAGE(F29:LI29) -> 0.014040827 | D29: =LOOKUP(2,1/(F29:XA29<>""),F29:XA29) -> 0.01162037 | F29: 0.012974537 | G29: 0.022372685 | H29: 0.014895833 | I29: 0.013402778 | J29: 0.015011574 | K29: 0.013252315 | L29: 0.020706019 | M29: 0.012488426 | N29: 0.01193287 | O29: 0.033657407 | P29: 0.012569444 | Q29: 0.011435185 | R29: 0.016574074 | S29: 0.012997685 | T29: 0.012060185 | U29: 0.018738426 | V29: 0.010023148 | W29: 0.013506944 | X29: 0.019976852 | Y29: 0.010983796 | Z29: 0.013298611 | AA29: 0.011886574 | AB29: 0.015 | AC29: 0.011435185 | AD29: 0.013356481 | AE29: 0.0093865741 | AF29: 0.014340278 | AG29: 0.011412037 | AH29: 0.013923611 | AI29: 0.015474537 | AJ29: 0.013483796 | AK29: 0.011898148 | AL29: 0.012789352 | AM29: 0.014236111 | AN29: 0.031793981 | AO29: 0.0090740741 | AP29: 0.013101852 | AQ29: 0.010393519 | AR29: 0.011273148 | AS29: 0.0097916667 | AT29: 0.021550926 | AU29: 0.037106481 | AV29: 0.014247685 | AW29: 0.011909722 | AX29: 0.015451389 | AY29: 0.016956019 | AZ29: 0.010706019 | BA29: 0.014074074 | BB29: 0.013553241 | BC29: 0.015717593 | BD29: 0.014537037 | BE29: 0.016365741 | BF29: 0.011585648 | BG29: 0.010590278 | BH29: 0.013773148 | BI29: 0.022268519 | BJ29: 0.012361111 | BK29: 0.010590278 | BL29: 0.01244213 | BM29: 0.012777778 | BN29: 0.01037037 | BO29: 0.012696759 | BP29: 0.014791667 | BQ29: 0.016516204 | BR29: 0.011134259 | BS29: 0.013680556 | BT29: 0.01462963 | BU29: 0.018090278 | BV29: 0.016412037 | BW29: 0.0082060185 | BX29: 0.012696759 | BY29: 0.013958333 | BZ29: 0.012233796 | CA29: 0.0121875 | CB29: 0.011770833 | CC29: 0.01755787 | CD29: 0.010127315 | CE29: 0.011296296 | CF29: 0.0125 | CG29: 0.013703704 | CH29: 0.015439815 | CI29: 0.013715278 | CJ29: 0.0096875 | CK29: 0.010428241 | CL29: 0.012268519 | CM29: 0.0121875 | CN29: 0.0091319444 | CO29: 0.01369213 | CP29: 0.0096412037 | CQ29: 0.012233796 | CR29: 0.014131944 | CS29: 0.013043981 | CT29: 0.0092939815 | CU29: 0.017372685 | CV29: 0.0095486111 | CW29: 0.012743056 | CX29: 0.015810185 | CY29: 0.012777778 | CZ29: 0.010810185 | DA29: 0.010694444 | DB29: 0.01 | DC29: 0.01287037 | DD29: 0.015219907 | DE29: 0.018449074 | DF29: 0.01380787 | DG29: 0.017615741 | DH29: 0.013703704 | DI29: 0.026550926 | DJ29: 0.027858796 | DK29: 0.011516204 | DL29: 0.012997685 | DM29: 0.03625 | DN29: 0.019652778 | DO29: 0.0121875 | DP29: 0.010752315 | DQ29: 0.015868056 | DR29: 0.012835648 | DS29: 0.015081019 | DT29: 0.016157407 | DU29: 0.020150463 | DV29: 0.011840278 | DW29: 0.011875 | DX29: 0.014988426 | DY29: 0.011516204 | DZ29: 0.012106481 | EA29: 0.0125 | EB29: 0.015520833 | EC29: 0.012083333 | ED29: 0.011111111 | EE29: 0.0109375 | EF29: 0.011886574 | EG29: 0.013888889 | EH29: 0.0096643519 | EI29: 0.013680556 | EJ29: 0.016412037 | EK29: 0.013229167 | EL29: 0.012384259 | EM29: 0.011805556 | EN29: 0.017384259 | EO29: 0.013217593 | EP29: 0.012233796 | EQ29: 0.019178241 | ER29: 0.014907407 | ES29: 0.027905093 | ET29: 0.017256944 | EU29: 0.01806713 | EV29: 0.014918981 | EW29: 0.015277778 | EX29: 0.0115625 | EY29: 0.01525463 | EZ29: 0.011134259 | FA29: 0.011388889 | FB29: 0.017627315 | FC29: 0.012800926 | FD29: 0.010729167 | FE29: 0.01556713 | FF29: 0.013194444 | FG29: 0.0096643519 | FH29: 0.01275463 | FI29: 0.017731481 | FJ29: 0.011990741 | FK29: 0.011712963 | FL29: 0.012152778 | FM29: 0.014027778 | FN29: 0.012025463 | FO29: 0.01349537 | FP29: 0.010196759 | FQ29: 0.0019444444 | FR29: 0 | FS29: 0.022268519 | FT29: 0.013032407 | FU29: 0.01318287 | FV29: 0.013356481 | FW29: 0.023888889 | FX29: 0.014328704 | FY29: 0.011111111 | FZ29: 0.013645833 | GA29: 0.011412037 | GB29: 0.02587963 | GC29: 0.011458333 | GD29: 0.011099537 | GE29: 0.011099537 | GF29: 0.012650463 | GG29: 0.013993056 | GH29: 0.011226852 | GI29: 0.014212963 | GJ29: 0.015891204 | GK29: 0.011909722 | GL29: 0.012256944 | GM29: 0.013206019 | GN29: 0.013715278 | GO29: 0.016006944 | GP29: 0.010092593 | GQ29: 0.015046296 | GR29: 0.011701389 | GS29: 0.013101852 | GT29: 0.010520833 | GU29: 0.01568287 | GV29: 0.0115625 | GW29: 0.0096296296 | GX29: 0.013159722 | GY29: 0.013159722 | GZ29: 0.011435185 | HA29: 0.011354167 | HB29: 0.012303241 | HC29: 0.0097453704 | HD29: 0.016458333 | HE29: 0.017418981 | HF29: 0.012118056 | HG29: 0.014016204 | HH29: 0.015405093 | HI29: 0.027384259 | HJ29: 0.01275463 | HK29: 0.013530093 | HL29: 0.013842593 | HM29: 0.012025463 | HN29: 0.0084259259 | HO29: 0.010416667 | HP29: 0.011493056 | HQ29: 0.01125 | HR29: 0.011238426 | HS29: 0.013125 | HT29: 0.014027778 | HU29: 0.011643519 | HV29: 0.011608796 | HW29: 0.012523148 | HX29: 0.020983796 | HY29: 0.0095949074 | HZ29: 0.012708333 | IA29: 0.011712963 | IB29: 0.014861111 | IC29: 0.011689815 | ID29: 0.013483796 | IE29: 0.013252315 | IF29: 0.014803241 | IG29: 0.014803241 | IH29: 0.016238426 | II29: 0.012199074 | IJ29: 0.012662037 | IK29: 0.017476852 | IL29: 0.011018519 | IM29: 0.020763889 | IN29: 0.013564815 | IO29: 0.015960648 | IP29: 0.012071759 | IQ29: 0.014456019 | IR29: 0.014166667 | IS29: 0.023958333 | IT29: 0.012384259 | IU29: 0.02724537 | IV29: 0.015648148 | IW29: 0.01287037 | IX29: 0.01724537 | IY29: 0.010324074 | IZ29: 0.020821759 | JA29: 0.015833333 | JB29: 0.010289352 | JC29: 0.01212963 | JD29: 0.013518519 | JE29: 0.013159722 | JF29: 0.011099537 | JG29: 0.014837963 | JH29: 0.010532407 | JI29: 0.0099305556 | JJ29: 0.02224537 | JK29: 0.012939815 | JL29: 0.014305556 | JM29: 0.011226852 | JN29: 0.013668981 | JO29: 0.013599537 | JP29: 0.013877315 | JQ29: 0.010729167 | JR29: 0.0171875 | JS29: 0.025601852 | JT29: 0.010104167 | JU29: 0.015543981 | JV29: 0.010150463 | JW29: 0.010902778 | JX29: 0.012523148 | JY29: 0.015891204 | JZ29: 0.012905093 | KA29: 0.017881944 | KB29: 0.014594907 | KC29: 0.013472222 | KD29: 0.015347222 | KE29: 0.015486111 | KF29: 0.013483796 | KG29: 0.014386574 | KH29: 0.010960648 | KI29: 0.012893519 | KJ29: 0.013946759 | KK29: 0.012800926 | KL29: 0.012002315 | KM29: 0.013738426 | KN29: 0.013831019 | KO29: 0.017951389 | KP29: 0.011967593 | KQ29: 0.012962963 | KR29: 0.013344907 | KS29: 0.014224537 | KT29: 0.015659722 | KU29: 0.023101852 | KV29: 0.012233796 | KW29: 0.015439815 | KX29: 0.010474537 | KY29: 0.01162037
